Workbook

Sheet Product_Master
A1: Product_ID | B1: Product_Name | C1: Category | D1: Standard_Lead_Time
A2: P001 | B2: Yogurt 1 | C2: Dairy | D2: 3
A3: P002 | B3: Formula 2 | C3: Nutrition | D3: 2
A4: P003 | B4: Juice 3 | C4: Beverages | D4: 6
A5: P004 | B5: Snack Bar 4 | C5: Snacks | D5: 5
A6: P005 | B6: Oat Cereal 5 | C6: Cereals | D6: 5
A7: P006 | B7: Milk 6 | C7: Dairy | D7: 4
A8: P007 | B8: Nutrition Drink 7 | C8: Nutrition | D8: 3
A9: P008 | B9: Water 8 | C9: Beverages | D9: 10
A10: P009 | B10: Cracker 9 | C10: Snacks | D10: 3
A11: P010 | B11: Corn Flakes 10 | C11: Cereals | D11: 8
A12: P011 | B12: Cheese 11 | C12: Dairy | D12: 2
A13: P012 | B13: Powder Mix 12 | C13: Nutrition | D13: 2
... A101: P100 | B101: Rice Cereal 100 | C101: Cereals | D101: 5

Sheet Planning_Data
A1: ` | B1: Product_ID | C1: Planning_Date | D1: Planned_Quantity | E1: Lead_Time_Days | F1: Minimum_Order_Qty | G1: Product_ID_Check | H1: Duplicate_Check | I1: Quantity_Check | J1: Lead_Time_Check | K1: Minimum_Order_Check | L1: Product_Existence_Check | M1: Planning_Date_Check | N1: Overall_Data_Quality | P1: Needs_Review_Count | Q1: Good_Records | R1: Data_Quality_Percentage
A2: PL001 | B2: P018 | C2: 46050 | D2: 1000 | E2: 9 | F2: 50 | G2: =IF(B2="","Missing Product ID","Present") -> Present | H2: =IF(COUNTIF(A:A,A2)>1,"Duplicate","Unique") -> Unique | I2: =IF(D2="","Missing",IF(D2<=0,"Invalid Quantity","Valid")) -> Valid | J2: =IF(E2="","Missing",IF(E2<=0,"Invalid Lead Time","Valid")) -> Valid | K2: =IF(F2="","Missing",IF(F2<=0,"Invalid","Valid")) -> Valid | L2: =IF(B2="","Missing Product ID",IF(COUNTIF(Product_Master!A:A,B2)>0,"Found","Not Found")) -> Found | M2: =IF(C2="","Missing Date",IF(ISNUMBER(C2),"Valid Date","Invalid Date")) -> Valid Date | N2: =IF(OR(H2="Duplicate",I2<>"Valid",J2<>"Valid",K2<>"Valid",L2<>"Found",M2<>"Valid Date"),"Needs Review","Good") -> Good | P2: =COUNTIF(N:N,"Needs Review") -> 11 | Q2: =COUNTIF(N:N,"Good") -> 189 | R2: =Q2/(Q2+P2) -> 0.945
A3: PL002 | B3: P015 | C3: 46298 | D3: 200 | E3: 4 | F3: 200 | G3: =IF(B3="","Missing Product ID","Present") -> Present | H3: =IF(COUNTIF(A:A,A3)>1,"Duplicate","Unique") -> Unique | I3: =IF(D3="","Missing",IF(D3<=0,"Invalid Quantity","Valid")) -> Valid | J3: =IF(E3="","Missing",IF(E3<=0,"Invalid Lead Time","Valid")) -> Valid | K3: =IF(F3="","Missing",IF(F3<=0,"Invalid","Valid")) -> Valid | L3: =IF(B3="","Missing Product ID",IF(COUNTIF(Product_Master!A:A,B3)>0,"Found","Not Found")) -> Found | M3: =IF(C3="","Missing Date",IF(ISNUMBER(C3),"Valid Date","Invalid Date")) -> Valid Date | N3: =IF(OR(H3="Duplicate",I3<>"Valid",J3<>"Valid",K3<>"Valid",L3<>"Found",M3<>"Valid Date"),"Needs Review","Good") -> Good
A4: PL003 | B4: P050 | C4: 46160 | D4: 500 | E4: 9 | F4: 250 | G4: =IF(B4="","Missing Product ID","Present") -> Present | H4: =IF(COUNTIF(A:A,A4)>1,"Duplicate","Unique") -> Unique | I4: =IF(D4="","Missing",IF(D4<=0,"Invalid Quantity","Valid")) -> Valid | J4: =IF(E4="","Missing",IF(E4<=0,"Invalid Lead Time","Valid")) -> Valid | K4: =IF(F4="","Missing",IF(F4<=0,"Invalid","Valid")) -> Valid | L4: =IF(B4="","Missing Product ID",IF(COUNTIF(Product_Master!A:A,B4)>0,"Found","Not Found")) -> Found | M4: =IF(C4="","Missing Date",IF(ISNUMBER(C4),"Valid Date","Invalid Date")) -> Valid Date | N4: =IF(OR(H4="Duplicate",I4<>"Valid",J4<>"Valid",K4<>"Valid",L4<>"Found",M4<>"Valid Date"),"Needs Review","Good") -> Good
A5: PL004 | B5: P002 | C5: 46337 | D5: 150 | E5: 10 | F5: 150 | G5: =IF(B5="","Missing Product ID","Present") -> Present | H5: =IF(COUNTIF(A:A,A5)>1,"Duplicate","Unique") -> Unique | I5: =IF(D5="","Missing",IF(D5<=0,"Invalid Quantity","Valid")) -> Valid | J5: =IF(E5="","Missing",IF(E5<=0,"Invalid Lead Time","Valid")) -> Valid | K5: =IF(F5="","Missing",IF(F5<=0,"Invalid","Valid")) -> Valid | L5: =IF(B5="","Missing Product ID",IF(COUNTIF(Product_Master!A:A,B5)>0,"Found","Not Found")) -> Found | M5: =IF(C5="","Missing Date",IF(ISNUMBER(C5),"Valid Date","Invalid Date")) -> Valid Date | N5: =IF(OR(H5="Duplicate",I5<>"Valid",J5<>"Valid",K5<>"Valid",L5<>"Found",M5<>"Valid Date"),"Needs Review","Good") -> Good
A6: PL005 | B6: P015 | C6: 46235 | D6: 300 | E6: 8 | F6: 100 | G6: =IF(B6="","Missing Product ID","Present") -> Present | H6: =IF(COUNTIF(A:A,A6)>1,"Duplicate","Unique") -> Unique | I6: =IF(D6="","Missing",IF(D6<=0,"Invalid Quantity","Valid")) -> Valid | J6: =IF(E6="","Missing",IF(E6<=0,"Invalid Lead Time","Valid")) -> Valid | K6: =IF(F6="","Missing",IF(F6<=0,"Invalid","Valid")) -> Valid | L6: =IF(B6="","Missing Product ID",IF(COUNTIF(Product_Master!A:A,B6)>0,"Found","Not Found")) -> Found | M6: =IF(C6="","Missing Date",IF(ISNUMBER(C6),"Valid Date","Invalid Date")) -> Valid Date | N6: =IF(OR(H6="Duplicate",I6<>"Valid",J6<>"Valid",K6<>"Valid",L6<>"Found",M6<>"Valid Date"),"Needs Review","Good") -> Good
A7: PL006 | B7: P093 | C7: 46269 | D7: 300 | E7: 10 | F7: 100 | G7: =IF(B7="","Missing Product ID","Present") -> Present | H7: =IF(COUNTIF(A:A,A7)>1,"Duplicate","Unique") -> Unique | I7: =IF(D7="","Missing",IF(D7<=0,"Invalid Quantity","Valid")) -> Valid | J7: =IF(E7="","Missing",IF(E7<=0,"Invalid Lead Time","Valid")) -> Valid | K7: =IF(F7="","Missing",IF(F7<=0,"Invalid","Valid")) -> Valid | L7: =IF(B7="","Missing Product ID",IF(COUNTIF(Product_Master!A:A,B7)>0,"Found","Not Found")) -> Found | M7: =IF(C7="","Missing Date",IF(ISNUMBER(C7),"Valid Date","Invalid Date")) -> Valid Date | N7: =IF(OR(H7="Duplicate",I7<>"Valid",J7<>"Valid",K7<>"Valid",L7<>"Found",M7<>"Valid Date"),"Needs Review","Good") -> Good
A8: PL007 | B8: P081 | C8: 46117 | D8: 300 | E8: 10 | F8: 250 | G8: =IF(B8="","Missing Product ID","Present") -> Present | H8: =IF(COUNTIF(A:A,A8)>1,"Duplicate","Unique") -> Unique | I8: =IF(D8="","Missing",IF(D8<=0,"Invalid Quantity","Valid")) -> Valid | J8: =IF(E8="","Missing",IF(E8<=0,"Invalid Lead Time","Valid")) -> Valid | K8: =IF(F8="","Missing",IF(F8<=0,"Invalid","Valid")) -> Valid | L8: =IF(B8="","Missing Product ID",IF(COUNTIF(Product_Master!A:A,B8)>0,"Found","Not Found")) -> Found | M8: =IF(C8="","Missing Date",IF(ISNUMBER(C8),"Valid Date","Invalid Date")) -> Valid Date | N8: =IF(OR(H8="Duplicate",I8<>"Valid",J8<>"Valid",K8<>"Valid",L8<>"Found",M8<>"Valid Date"),"Needs Review","Good") -> Good
A9: PL008 | B9: P048 | C9: 46042 | D9: 200 | E9: 10 | F9: 250 | G9: =IF(B9="","Missing Product ID","Present") -> Present | H9: =IF(COUNTIF(A:A,A9)>1,"Duplicate","Unique") -> Unique | I9: =IF(D9="","Missing",IF(D9<=0,"Invalid Quantity","Valid")) -> Valid | J9: =IF(E9="","Missing",IF(E9<=0,"Invalid Lead Time","Valid")) -> Valid | K9: =IF(F9="","Missing",IF(F9<=0,"Invalid","Valid")) -> Valid | L9: =IF(B9="","Missing Product ID",IF(COUNTIF(Product_Master!A:A,B9)>0,"Found","Not Found")) -> Found | M9: =IF(C9="","Missing Date",IF(ISNUMBER(C9),"Valid Date","Invalid Date")) -> Valid Date | N9: =IF(OR(H9="Duplicate",I9<>"Valid",J9<>"Valid",K9<>"Valid",L9<>"Found",M9<>"Valid Date"),"Needs Review","Good") -> Good
A10: PL009 | B10: P999 | C10: 46200 | D10: 750 | E10: 2 | F10: 50 | G10: =IF(B10="","Missing Product ID","Present") -> Present | H10: =IF(COUNTIF(A:A,A10)>1,"Duplicate","Unique") -> Unique | I10: =IF(D10="","Missing",IF(D10<=0,"Invalid Quantity","Valid")) -> Valid | J10: =IF(E10="","Missing",IF(E10<=0,"Invalid Lead Time","Valid")) -> Valid | K10: =IF(F10="","Missing",IF(F10<=0,"Invalid","Valid")) -> Valid | L10: =IF(B10="","Missing Product ID",IF(COUNTIF(Product_Master!A:A,B10)>0,"Found","Not Found")) -> Not Found | M10: =IF(C10="","Missing Date",IF(ISNUMBER(C10),"Valid Date","Invalid Date")) -> Valid Date | N10: =IF(OR(H10="Duplicate",I10<>"Valid",J10<>"Valid",K10<>"Valid",L10<>"Found",M10<>"Valid Date"),"Needs Review","Good") -> Needs Review
A11: PL010 | B11: P040 | C11: 46298 | D11: 250 | E11: 2 | F11: 100 | G11: =IF(B11="","Missing Product ID","Present") -> Present | H11: =IF(COUNTIF(A:A,A11)>1,"Duplicate","Unique") -> Unique | I11: =IF(D11="","Missing",IF(D11<=0,"Invalid Quantity","Valid")) -> Valid | J11: =IF(E11="","Missing",IF(E11<=0,"Invalid Lead Time","Valid")) -> Valid | K11: =IF(F11="","Missing",IF(F11<=0,"Invalid","Valid")) -> Valid | L11: =IF(B11="","Missing Product ID",IF(COUNTIF(Product_Master!A:A,B11)>0,"Found","Not Found")) -> Found | M11: =IF(C11="","Missing Date",IF(ISNUMBER(C11),"Valid Date","Invalid Date")) -> Valid Date | N11: =IF(OR(H11="Duplicate",I11<>"Valid",J11<>"Valid",K11<>"Valid",L11<>"Found",M11<>"Valid Date"),"Needs Review","Good") -> Good
A12: PL011 | B12: P011 | C12: 46086 | D12: 750 | E12: 3 | F12: 250 | G12: =IF(B12="","Missing Product ID","Present") -> Present | H12: =IF(COUNTIF(A:A,A12)>1,"Duplicate","Unique") -> Unique | I12: =IF(D12="","Missing",IF(D12<=0,"Invalid Quantity","Valid")) -> Valid | J12: =IF(E12="","Missing",IF(E12<=0,"Invalid Lead Time","Valid")) -> Valid | K12: =IF(F12="","Missing",IF(F12<=0,"Invalid","Valid")) -> Valid | L12: =IF(B12="","Missing Product ID",IF(COUNTIF(Product_Master!A:A,B12)>0,"Found","Not Found")) -> Found | M12: =IF(C12="","Missing Date",IF(ISNUMBER(C12),"Valid Date","Invalid Date")) -> Valid Date | N12: =IF(OR(H12="Duplicate",I12<>"Valid",J12<>"Valid",K12<>"Valid",L12<>"Found",M12<>"Valid Date"),"Needs Review","Good") -> Good
A13: PL012 | B13: P085 | C13: 46159 | D13: 750 | E13: 10 | F13: 100 | G13: =IF(B13="","Missing Product ID","Present") -> Present | H13: =IF(COUNTIF(A:A,A13)>1,"Duplicate","Unique") -> Unique | I13: =IF(D13="","Missing",IF(D13<=0,"Invalid Quantity","Valid")) -> Valid | J13: =IF(E13="","Missing",IF(E13<=0,"Invalid Lead Time","Valid")) -> Valid | K13: =IF(F13="","Missing",IF(F13<=0,"Invalid","Valid")) -> Valid | L13: =IF(B13="","Missing Product ID",IF(COUNTIF(Product_Master!A:A,B13)>0,"Found","Not Found")) -> Found | M13: =IF(C13="","Missing Date",IF(ISNUMBER(C13),"Valid Date","Invalid Date")) -> Valid Date | N13: =IF(OR(H13="Duplicate",I13<>"Valid",J13<>"Valid",K13<>"Valid",L13<>"Found",M13<>"Valid Date"),"Needs Review","Good") -> Good
A14: PL013 | B14: P078 | C14: 46379 | D14: 500 | E14: 5 | F14: 250 | G14: =IF(B14="","Missing Product ID","Present") -> Present | H14: =IF(COUNTIF(A:A,A14)>1,"Duplicate","Unique") -> Unique | I14: =IF(D14="","Missing",IF(D14<=0,"Invalid Quantity","Valid")) -> Valid | J14: =IF(E14="","Missing",IF(E14<=0,"Invalid Lead Time","Valid")) -> Valid | K14: =IF(F14="","Missing",IF(F14<=0,"Invalid","Valid")) -> Valid | L14: =IF(B14="","Missing Product ID",IF(COUNTIF(Product_Master!A:A,B14)>0,"Found","Not Found")) -> Found | M14: =IF(C14="","Missing Date",IF(ISNUMBER(C14),"Valid Date","Invalid Date")) -> Valid Date | N14: =IF(OR(H14="Duplicate",I14<>"Valid",J14<>"Valid",K14<>"Valid",L14<>"Found",M14<>"Valid Date"),"Needs Review","Good") -> Good
... A42: PL041 | B42: P037 | C42: 46366 | D42: 200 | E42: 9 | F42: 250 | G42: =IF(B42="","Missing Product ID","Present") -> Present | H42: =IF(COUNTIF(A:A,A42)>1,"Duplicate","Unique") -> Unique | I42: =IF(D42="","Missing",IF(D42<=0,"Invalid Quantity","Valid")) -> Valid | J42: =IF(E42="","Missing",IF(E42<=0,"Invalid Lead Time","Valid")) -> Valid | K42: =IF(F42="","Missing",IF(F42<=0,"Invalid","Valid")) -> Valid | L42: =IF(B42="","Missing Product ID",IF(COUNTIF(Product_Master!A:A,B42)>0,"Found","Not Found")) -> Found | M42: =IF(C42="","Missing Date",IF(ISNUMBER(C42),"Valid Date","Invalid Date")) -> Valid Date | N42: =IF(OR(H42="Duplicate",I42<>"Valid",J42<>"Valid",K42<>"Valid",L42<>"Found",M42<>"Valid Date"),"Needs Review","Good") -> Good
A43: PL042 | C43: 46164 | D43: 1000 | E43: 2 | F43: 250 | G43: =IF(B43="","Missing Product ID","Present") -> Missing Product ID | H43: =IF(COUNTIF(A:A,A43)>1,"Duplicate","Unique") -> Unique | I43: =IF(D43="","Missing",IF(D43<=0,"Invalid Quantity","Valid")) -> Valid | J43: =IF(E43="","Missing",IF(E43<=0,"Invalid Lead Time","Valid")) -> Valid | K43: =IF(F43="","Missing",IF(F43<=0,"Invalid","Valid")) -> Valid | L43: =IF(B43="","Missing Product ID",IF(COUNTIF(Product_Master!A:A,B43)>0,"Found","Not Found")) -> Missing Product ID | M43: =IF(C43="","Missing Date",IF(ISNUMBER(C43),"Valid Date","Invalid Date")) -> Valid Date | N43: =IF(OR(H43="Duplicate",I43<>"Valid",J43<>"Valid",K43<>"Valid",L43<>"Found",M43<>"Valid Date"),"Needs Review","Good") -> Needs Review
A44: PL043 | B44: P014 | C44: 46077 | D44: 200 | E44: 6 | F44: 50 | G44: =IF(B44="","Missing Product ID","Present") -> Present | H44: =IF(COUNTIF(A:A,A44)>1,"Duplicate","Unique") -> Unique | I44: =IF(D44="","Missing",IF(D44<=0,"Invalid Quantity","Valid")) -> Valid | J44: =IF(E44="","Missing",IF(E44<=0,"Invalid Lead Time","Valid")) -> Valid | K44: =IF(F44="","Missing",IF(F44<=0,"Invalid","Valid")) -> Valid | L44: =IF(B44="","Missing Product ID",IF(COUNTIF(Product_Master!A:A,B44)>0,"Found","Not Found")) -> Found | M44: =IF(C44="","Missing Date",IF(ISNUMBER(C44),"Valid Date","Invalid Date")) -> Valid Date | N44: =IF(OR(H44="Duplicate",I44<>"Valid",J44<>"Valid",K44<>"Valid",L44<>"Found",M44<>"Valid Date"),"Needs Review","Good") -> Good
A45: PL044 | B45: P071 | C45: 46302 | D45: 200 | E45: 6 | F45: 150 | G45: =IF(B45="","Missing Product ID","Present") -> Present | H45: =IF(COUNTIF(A:A,A45)>1,"Duplicate","Unique") -> Unique | I45: =IF(D45="","Missing",IF(D45<=0,"Invalid Quantity","Valid")) -> Valid | J45: =IF(E45="","Missing",IF(E45<=0,"Invalid Lead Time","Valid")) -> Valid | K45: =IF(F45="","Missing",IF(F45<=0,"Invalid","Valid")) -> Valid | L45: =IF(B45="","Missing Product ID",IF(COUNTIF(Product_Master!A:A,B45)>0,"Found","Not Found")) -> Found | M45: =IF(C45="","Missing Date",IF(ISNUMBER(C45),"Valid Date","Invalid Date")) -> Valid Date | N45: =IF(OR(H45="Duplicate",I45<>"Valid",J45<>"Valid",K45<>"Valid",L45<>"Found",M45<>"Valid Date"),"Needs Review","Good") -> Good
A46: PL045 | B46: P092 | C46: 46281 | D46: 400 | E46: 5 | F46: 150 | G46: =IF(B46="","Missing Product ID","Present") -> Present | H46: =IF(COUNTIF(A:A,A46)>1,"Duplicate","Unique") -> Unique | I46: =IF(D46="","Missing",IF(D46<=0,"Invalid Quantity","Valid")) -> Valid | J46: =IF(E46="","Missing",IF(E46<=0,"Invalid Lead Time","Valid")) -> Valid | K46: =IF(F46="","Missing",IF(F46<=0,"Invalid","Valid")) -> Valid | L46: =IF(B46="","Missing Product ID",IF(COUNTIF(Product_Master!A:A,B46)>0,"Found","Not Found")) -> Found | M46: =IF(C46="","Missing Date",IF(ISNUMBER(C46),"Valid Date","Invalid Date")) -> Valid Date | N46: =IF(OR(H46="Duplicate",I46<>"Valid",J46<>"Valid",K46<>"Valid",L46<>"Found",M46<>"Valid Date"),"Needs Review","Good") -> Good
A47: PL046 | B47: P033 | C47: 46144 | D47: 100 | E47: 3 | F47: 200 | G47: =IF(B47="","Missing Product ID","Present") -> Present | H47: =IF(COUNTIF(A:A,A47)>1,"Duplicate","Unique") -> Unique | I47: =IF(D47="","Missing",IF(D47<=0,"Invalid Quantity","Valid")) -> Valid | J47: =IF(E47="","Missing",IF(E47<=0,"Invalid Lead Time","Valid")) -> Valid | K47: =IF(F47="","Missing",IF(F47<=0,"Invalid","Valid")) -> Valid | L47: =IF(B47="","Missing Product ID",IF(COUNTIF(Product_Master!A:A,B47)>0,"Found","Not Found")) -> Found | M47: =IF(C47="","Missing Date",IF(ISNUMBER(C47),"Valid Date","Invalid Date")) -> Valid Date | N47: =IF(OR(H47="Duplicate",I47<>"Valid",J47<>"Valid",K47<>"Valid",L47<>"Found",M47<>"Valid Date"),"Needs Review","Good") -> Good
A48: PL047 | B48: P001 | C48: 46105 | D48: 400 | E48: 4 | F48: 150 | G48: =IF(B48="","Missing Product ID","Present") -> Present | H48: =IF(COUNTIF(A:A,A48)>1,"Duplicate","Unique") -> Unique | I48: =IF(D48="","Missing",IF(D48<=0,"Invalid Quantity","Valid")) -> Valid | J48: =IF(E48="","Missing",IF(E48<=0,"Invalid Lead Time","Valid")) -> Valid | K48: =IF(F48="","Missing",IF(F48<=0,"Invalid","Valid")) -> Valid | L48: =IF(B48="","Missing Product ID",IF(COUNTIF(Product_Master!A:A,B48)>0,"Found","Not Found")) -> Found | M48: =IF(C48="","Missing Date",IF(ISNUMBER(C48),"Valid Date","Invalid Date")) -> Valid Date | N48: =IF(OR(H48="Duplicate",I48<>"Valid",J48<>"Valid",K48<>"Valid",L48<>"Found",M48<>"Valid Date"),"Needs Review","Good") -> Good
A49: PL048 | B49: P057 | C49: 46026 | D49: 1000 | E49: 8 | F49: 250 | G49: =IF(B49="","Missing Product ID","Present") -> Present | H49: =IF(COUNTIF(A:A,A49)>1,"Duplicate","Unique") -> Unique | I49: =IF(D49="","Missing",IF(D49<=0,"Invalid Quantity","Valid")) -> Valid | J49: =IF(E49="","Missing",IF(E49<=0,"Invalid Lead Time","Valid")) -> Valid | K49: =IF(F49="","Missing",IF(F49<=0,"Invalid","Valid")) -> Valid | L49: =IF(B49="","Missing Product ID",IF(COUNTIF(Product_Master!A:A,B49)>0,"Found","Not Found")) -> Found | M49: =IF(C49="","Missing Date",IF(ISNUMBER(C49),"Valid Date","Invalid Date")) -> Valid Date | N49: =IF(OR(H49="Duplicate",I49<>"Valid",J49<>"Valid",K49<>"Valid",L49<>"Found",M49<>"Valid Date"),"Needs Review","Good") -> Good
A50: PL049 | B50: P010 | C50: 46192 | D50: 200 | E50: 10 | F50: 50 | G50: =IF(B50="","Missing Product ID","Present") -> Present | H50: =IF(COUNTIF(A:A,A50)>1,"Duplicate","Unique") -> Unique | I50: =IF(D50="","Missing",IF(D50<=0,"Invalid Quantity","Valid")) -> Valid | J50: =IF(E50="","Missing",IF(E50<=0,"Invalid Lead Time","Valid")) -> Valid | K50: =IF(F50="","Missing",IF(F50<=0,"Invalid","Valid")) -> Valid | L50: =IF(B50="","Missing Product ID",IF(COUNTIF(Product_Master!A:A,B50)>0,"Found","Not Found")) -> Found | M50: =IF(C50="","Missing Date",IF(ISNUMBER(C50),"Valid Date","Invalid Date")) -> Valid Date | N50: =IF(OR(H50="Duplicate",I50<>"Valid",J50<>"Valid",K50<>"Valid",L50<>"Found",M50<>"Valid Date"),"Needs Review","Good") -> Good
A51: PL050 | B51: P071 | C51: 46032 | D51: 200 | E51: 8 | F51: 100 | G51: =IF(B51="","Missing Product ID","Present") -> Present | H51: =IF(COUNTIF(A:A,A51)>1,"Duplicate","Unique") -> Duplicate | I51: =IF(D51="","Missing",IF(D51<=0,"Invalid Quantity","Valid")) -> Valid | J51: =IF(E51="","Missing",IF(E51<=0,"Invalid Lead Time","Valid")) -> Valid | K51: =IF(F51="","Missing",IF(F51<=0,"Invalid","Valid")) -> Valid | L51: =IF(B51="","Missing Product ID",IF(COUNTIF(Product_Master!A:A,B51)>0,"Found","Not Found")) -> Found | M51: =IF(C51="","Missing Date",IF(ISNUMBER(C51),"Valid Date","Invalid Date")) -> Valid Date | N51: =IF(OR(H51="Duplicate",I51<>"Valid",J51<>"Valid",K51<>"Valid",L51<>"Found",M51<>"Valid Date"),"Needs Review","Good") -> Needs Review
A52: PL050 | B52: P047 | C52: 46334 | D52: 100 | E52: 7 | F52: 100 | G52: =IF(B52="","Missing Product ID","Present") -> Present | H52: =IF(COUNTIF(A:A,A52)>1,"Duplicate","Unique") -> Duplicate | I52: =IF(D52="","Missing",IF(D52<=0,"Invalid Quantity","Valid")) -> Valid | J52: =IF(E52="","Missing",IF(E52<=0,"Invalid Lead Time","Valid")) -> Valid | K52: =IF(F52="","Missing",IF(F52<=0,"Invalid","Valid")) -> Valid | L52: =IF(B52="","Missing Product ID",IF(COUNTIF(Product_Master!A:A,B52)>0,"Found","Not Found")) -> Found | M52: =IF(C52="","Missing Date",IF(ISNUMBER(C52),"Valid Date","Invalid Date")) -> Valid Date | N52: =IF(OR(H52="Duplicate",I52<>"Valid",J52<>"Valid",K52<>"Valid",L52<>"Found",M52<>"Valid Date"),"Needs Review","Good") -> Needs Review
A53: PL052 | B53: P086 | C53: 46223 | D53: 150 | E53: 7 | F53: 250 | G53: =IF(B53="","Missing Product ID","Present") -> Present | H53: =IF(COUNTIF(A:A,A53)>1,"Duplicate","Unique") -> Unique | I53: =IF(D53="","Missing",IF(D53<=0,"Invalid Quantity","Valid")) -> Valid | J53: =IF(E53="","Missing",IF(E53<=0,"Invalid Lead Time","Valid")) -> Valid | K53: =IF(F53="","Missing",IF(F53<=0,"Invalid","Valid")) -> Valid | L53: =IF(B53="","Missing Product ID",IF(COUNTIF(Product_Master!A:A,B53)>0,"Found","Not Found")) -> Found | M53: =IF(C53="","Missing Date",IF(ISNUMBER(C53),"Valid Date","Invalid Date")) -> Valid Date | N53: =IF(OR(H53="Duplicate",I53<>"Valid",J53<>"Valid",K53<>"Valid",L53<>"Found",M53<>"Valid Date"),"Needs Review","Good") -> Good
A54: PL053 | B54: P096 | C54: 46095 | D54: 200 | E54: 5 | F54: 100 | G54: =IF(B54="","Missing Product ID","Present") -> Present | H54: =IF(COUNTIF(A:A,A54)>1,"Duplicate","Unique") -> Unique | I54: =IF(D54="","Missing",IF(D54<=0,"Invalid Quantity","Valid")) -> Valid | J54: =IF(E54="","Missing",IF(E54<=0,"Invalid Lead Time","Valid")) -> Valid | K54: =IF(F54="","Missing",IF(F54<=0,"Invalid","Valid")) -> Valid | L54: =IF(B54="","Missing Product ID",IF(COUNTIF(Product_Master!A:A,B54)>0,"Found","Not Found")) -> Found | M54: =IF(C54="","Missing Date",IF(ISNUMBER(C54),"Valid Date","Invalid Date")) -> Valid Date | N54: =IF(OR(H54="Duplicate",I54<>"Valid",J54<>"Valid",K54<>"Valid",L54<>"Found",M54<>"Valid Date"),"Needs Review","Good") -> Good
A55: PL054 | B55: P004 | C55: 46354 | D55: 200 | E55: 7 | F55: 200 | G55: =IF(B55="","Missing Product ID","Present") -> Present | H55: =IF(COUNTIF(A:A,A55)>1,"Duplicate","Unique") -> Unique | I55: =IF(D55="","Missing",IF(D55<=0,"Invalid Quantity","Valid")) -> Valid | J55: =IF(E55="","Missing",IF(E55<=0,"Invalid Lead Time","Valid")) -> Valid | K55: =IF(F55="","Missing",IF(F55<=0,"Invalid","Valid")) -> Valid | L55: =IF(B55="","Missing Product ID",IF(COUNTIF(Product_Master!A:A,B55)>0,"Found","Not Found")) -> Found | M55: =IF(C55="","Missing Date",IF(ISNUMBER(C55),"Valid Date","Invalid Date")) -> Valid Date | N55: =IF(OR(H55="Duplicate",I55<>"Valid",J55<>"Valid",K55<>"Valid",L55<>"Found",M55<>"Valid Date"),"Needs Review","Good") -> Good
... A68: PL067 | B68: P038 | C68: 46225 | D68: 1000 | E68: 4 | F68: 100 | G68: =IF(B68="","Missing Product ID","Present") -> Present | H68: =IF(COUNTIF(A:A,A68)>1,"Duplicate","Unique") -> Unique | I68: =IF(D68="","Missing",IF(D68<=0,"Invalid Quantity","Valid")) -> Valid | J68: =IF(E68="","Missing",IF(E68<=0,"Invalid Lead Time","Valid")) -> Valid | K68: =IF(F68="","Missing",IF(F68<=0,"Invalid","Valid")) -> Valid | L68: =IF(B68="","Missing Product ID",IF(COUNTIF(Product_Master!A:A,B68)>0,"Found","Not Found")) -> Found | M68: =IF(C68="","Missing Date",IF(ISNUMBER(C68),"Valid Date","Invalid Date")) -> Valid Date | N68: =IF(OR(H68="Duplicate",I68<>"Valid",J68<>"Valid",K68<>"Valid",L68<>"Found",M68<>"Valid Date"),"Needs Review","Good") -> Good
A69: PL068 | B69: P049 | C69: 46292 | E69: 6 | F69: 200 | G69: =IF(B69="","Missing Product ID","Present") -> Present | H69: =IF(COUNTIF(A:A,A69)>1,"Duplicate","Unique") -> Unique | I69: =IF(D69="","Missing",IF(D69<=0,"Invalid Quantity","Valid")) -> Missing | J69: =IF(E69="","Missing",IF(E69<=0,"Invalid Lead Time","Valid")) -> Valid | K69: =IF(F69="","Missing",IF(F69<=0,"Invalid","Valid")) -> Valid | L69: =IF(B69="","Missing Product ID",IF(COUNTIF(Product_Master!A:A,B69)>0,"Found","Not Found")) -> Found | M69: =IF(C69="","Missing Date",IF(ISNUMBER(C69),"Valid Date","Invalid Date")) -> Valid Date | N69: =IF(OR(H69="Duplicate",I69<>"Valid",J69<>"Valid",K69<>"Valid",L69<>"Found",M69<>"Valid Date"),"Needs Review","Good") -> Needs Review
A70: PL069 | B70: P001 | C70: 46229 | D70: 300 | E70: 6 | F70: 100 | G70: =IF(B70="","Missing Product ID","Present") -> Present | H70: =IF(COUNTIF(A:A,A70)>1,"Duplicate","Unique") -> Unique | I70: =IF(D70="","Missing",IF(D70<=0,"Invalid Quantity","Valid")) -> Valid | J70: =IF(E70="","Missing",IF(E70<=0,"Invalid Lead Time","Valid")) -> Valid | K70: =IF(F70="","Missing",IF(F70<=0,"Invalid","Valid")) -> Valid | L70: =IF(B70="","Missing Product ID",IF(COUNTIF(Product_Master!A:A,B70)>0,"Found","Not Found")) -> Found | M70: =IF(C70="","Missing Date",IF(ISNUMBER(C70),"Valid Date","Invalid Date")) -> Valid Date | N70: =IF(OR(H70="Duplicate",I70<>"Valid",J70<>"Valid",K70<>"Valid",L70<>"Found",M70<>"Valid Date"),"Needs Review","Good") -> Good
A71: PL070 | B71: P075 | C71: 46256 | D71: 400 | E71: 9 | F71: 200 | G71: =IF(B71="","Missing Product ID","Present") -> Present | H71: =IF(COUNTIF(A:A,A71)>1,"Duplicate","Unique") -> Unique | I71: =IF(D71="","Missing",IF(D71<=0,"Invalid Quantity","Valid")) -> Valid | J71: =IF(E71="","Missing",IF(E71<=0,"Invalid Lead Time","Valid")) -> Valid | K71: =IF(F71="","Missing",IF(F71<=0,"Invalid","Valid")) -> Valid | L71: =IF(B71="","Missing Product ID",IF(COUNTIF(Product_Master!A:A,B71)>0,"Found","Not Found")) -> Found | M71: =IF(C71="","Missing Date",IF(ISNUMBER(C71),"Valid Date","Invalid Date")) -> Valid Date | N71: =IF(OR(H71="Duplicate",I71<>"Valid",J71<>"Valid",K71<>"Valid",L71<>"Found",M71<>"Valid Date"),"Needs Review","Good") -> Good
A72: PL071 | B72: P028 | C72: 46329 | D72: 1000 | E72: 9 | F72: 100 | G72: =IF(B72="","Missing Product ID","Present") -> Present | H72: =IF(COUNTIF(A:A,A72)>1,"Duplicate","Unique") -> Unique | I72: =IF(D72="","Missing",IF(D72<=0,"Invalid Quantity","Valid")) -> Valid | J72: =IF(E72="","Missing",IF(E72<=0,"Invalid Lead Time","Valid")) -> Valid | K72: =IF(F72="","Missing",IF(F72<=0,"Invalid","Valid")) -> Valid | L72: =IF(B72="","Missing Product ID",IF(COUNTIF(Product_Master!A:A,B72)>0,"Found","Not Found")) -> Found | M72: =IF(C72="","Missing Date",IF(ISNUMBER(C72),"Valid Date","Invalid Date")) -> Valid Date | N72: =IF(OR(H72="Duplicate",I72<>"Valid",J72<>"Valid",K72<>"Valid",L72<>"Found",M72<>"Valid Date"),"Needs Review","Good") -> Good
A73: PL072 | B73: P037 | C73: 46134 | D73: 1000 | E73: 7 | F73: 50 | G73: =IF(B73="","Missing Product ID","Present") -> Present | H73: =IF(COUNTIF(A:A,A73)>1,"Duplicate","Unique") -> Unique | I73: =IF(D73="","Missing",IF(D73<=0,"Invalid Quantity","Valid")) -> Valid | J73: =IF(E73="","Missing",IF(E73<=0,"Invalid Lead Time","Valid")) -> Valid | K73: =IF(F73="","Missing",IF(F73<=0,"Invalid","Valid")) -> Valid | L73: =IF(B73="","Missing Product ID",IF(COUNTIF(Product_Master!A:A,B73)>0,"Found","Not Found")) -> Found | M73: =IF(C73="","Missing Date",IF(ISNUMBER(C73),"Valid Date","Invalid Date")) -> Valid Date | N73: =IF(OR(H73="Duplicate",I73<>"Valid",J73<>"Valid",K73<>"Valid",L73<>"Found",M73<>"Valid Date"),"Needs Review","Good") -> Good
A74: PL073 | B74: P040 | C74: 46024 | D74: 250 | E74: 5 | F74: 100 | G74: =IF(B74="","Missing Product ID","Present") -> Present | H74: =IF(COUNTIF(A:A,A74)>1,"Duplicate","Unique") -> Unique | I74: =IF(D74="","Missing",IF(D74<=0,"Invalid Quantity","Valid")) -> Valid | J74: =IF(E74="","Missing",IF(E74<=0,"Invalid Lead Time","Valid")) -> Valid | K74: =IF(F74="","Missing",IF(F74<=0,"Invalid","Valid")) -> Valid | L74: =IF(B74="","Missing Product ID",IF(COUNTIF(Product_Master!A:A,B74)>0,"Found","Not Found")) -> Found | M74: =IF(C74="","Missing Date",IF(ISNUMBER(C74),"Valid Date","Invalid Date")) -> Valid Date | N74: =IF(OR(H74="Duplicate",I74<>"Valid",J74<>"Valid",K74<>"Valid",L74<>"Found",M74<>"Valid Date"),"Needs Review","Good") -> Good
A75: PL074 | B75: P032 | C75: 46224 | D75: 750 | E75: 3 | F75: 200 | G75: =IF(B75="","Missing Product ID","Present") -> Present | H75: =IF(COUNTIF(A:A,A75)>1,"Duplicate","Unique") -> Unique | I75: =IF(D75="","Missing",IF(D75<=0,"Invalid Quantity","Valid")) -> Valid | J75: =IF(E75="","Missing",IF(E75<=0,"Invalid Lead Time","Valid")) -> Valid | K75: =IF(F75="","Missing",IF(F75<=0,"Invalid","Valid")) -> Valid | L75: =IF(B75="","Missing Product ID",IF(COUNTIF(Product_Master!A:A,B75)>0,"Found","Not Found")) -> Found | M75: =IF(C75="","Missing Date",IF(ISNUMBER(C75),"Valid Date","Invalid Date")) -> Valid Date | N75: =IF(OR(H75="Duplicate",I75<>"Valid",J75<>"Valid",K75<>"Valid",L75<>"Found",M75<>"Valid Date"),"Needs Review","Good") -> Good
A76: PL075 | B76: P074 | C76: 46211 | D76: 250 | E76: 8 | F76: 200 | G76: =IF(B76="","Missing Product ID","Present") -> Present | H76: =IF(COUNTIF(A:A,A76)>1,"Duplicate","Unique") -> Unique | I76: =IF(D76="","Missing",IF(D76<=0,"Invalid Quantity","Valid")) -> Valid | J76: =IF(E76="","Missing",IF(E76<=0,"Invalid Lead Time","Valid")) -> Valid | K76: =IF(F76="","Missing",IF(F76<=0,"Invalid","Valid")) -> Valid | L76: =IF(B76="","Missing Product ID",IF(COUNTIF(Product_Master!A:A,B76)>0,"Found","Not Found")) -> Found | M76: =IF(C76="","Missing Date",IF(ISNUMBER(C76),"Valid Date","Invalid Date")) -> Valid Date | N76: =IF(OR(H76="Duplicate",I76<>"Valid",J76<>"Valid",K76<>"Valid",L76<>"Found",M76<>"Valid Date"),"Needs Review","Good") -> Good
A77: PL076 | B77: P019 | C77: 46118 | D77: 100 | E77: 3 | F77: 200 | G77: =IF(B77="","Missing Product ID","Present") -> Present | H77: =IF(COUNTIF(A:A,A77)>1,"Duplicate","Unique") -> Unique | I77: =IF(D77="","Missing",IF(D77<=0,"Invalid Quantity","Valid")) -> Valid | J77: =IF(E77="","Missing",IF(E77<=0,"Invalid Lead Time","Valid")) -> Valid | K77: =IF(F77="","Missing",IF(F77<=0,"Invalid","Valid")) -> Valid | L77: =IF(B77="","Missing Product ID",IF(COUNTIF(Product_Master!A:A,B77)>0,"Found","Not Found")) -> Found | M77: =IF(C77="","Missing Date",IF(ISNUMBER(C77),"Valid Date","Invalid Date")) -> Valid Date | N77: =IF(OR(H77="Duplicate",I77<>"Valid",J77<>"Valid",K77<>"Valid",L77<>"Found",M77<>"Valid Date"),"Needs Review","Good") -> Good
A78: PL077 | B78: P090 | C78: 46273 | D78: 1000 | E78: 9 | F78: 50 | G78: =IF(B78="","Missing Product ID","Present") -> Present | H78: =IF(COUNTIF(A:A,A78)>1,"Duplicate","Unique") -> Unique | I78: =IF(D78="","Missing",IF(D78<=0,"Invalid Quantity","Valid")) -> Valid | J78: =IF(E78="","Missing",IF(E78<=0,"Invalid Lead Time","Valid")) -> Valid | K78: =IF(F78="","Missing",IF(F78<=0,"Invalid","Valid")) -> Valid | L78: =IF(B78="","Missing Product ID",IF(COUNTIF(Product_Master!A:A,B78)>0,"Found","Not Found")) -> Found | M78: =IF(C78="","Missing Date",IF(ISNUMBER(C78),"Valid Date","Invalid Date")) -> Valid Date | N78: =IF(OR(H78="Duplicate",I78<>"Valid",J78<>"Valid",K78<>"Valid",L78<>"Found",M78<>"Valid Date"),"Needs Review","Good") -> Good
A79: PL078 | B79: P016 | C79: 46343 | D79: 750 | E79: 4 | F79: 200 | G79: =IF(B79="","Missing Product ID","Present") -> Present | H79: =IF(COUNTIF(A:A,A79)>1,"Duplicate","Unique") -> Unique | I79: =IF(D79="","Missing",IF(D79<=0,"Invalid Quantity","Valid")) -> Valid | J79: =IF(E79="","Missing",IF(E79<=0,"Invalid Lead Time","Valid")) -> Valid | K79: =IF(F79="","Missing",IF(F79<=0,"Invalid","Valid")) -> Valid | L79: =IF(B79="","Missing Product ID",IF(COUNTIF(Product_Master!A:A,B79)>0,"Found","Not Found")) -> Found | M79: =IF(C79="","Missing Date",IF(ISNUMBER(C79),"Valid Date","Invalid Date")) -> Valid Date | N79: =IF(OR(H79="Duplicate",I79<>"Valid",J79<>"Valid",K79<>"Valid",L79<>"Found",M79<>"Valid Date"),"Needs Review","Good") -> Good
...

Sheet Instructions
A1: Supply Chain Data Quality Project — Practice Workbook
A2: Purpose | B2: Use this fictional dataset to practise Excel data-quality checks relevant to entry-level data/reporting roles.
A3: Data volume | B3: Product_Master: 100 products (plus header). Planning_Data: 200 planning records (plus header).
A4: Important | B4: The data is fictional and is not real Danone data.
A5: Suggested tasks | B5: 1. Convert each dataset into an Excel Table (Ctrl+T).
B6: 2. Find missing values, duplicate Planning_IDs, unknown Product_IDs, negative/zero quantities, and invalid lead times.
B7: 3. Check dates and remove extra spaces from Product_IDs.
B8: 4. Use XLOOKUP to bring product name/category into Planning_Data.
B9: 5. Create a PivotTable to summarise planned quantity by category.
B10: 6. Create a separate Data_Quality_Checks sheet to record issue type, row/ID, and fix.
A11: Beginner note | B11: Do not fix the intentional issues immediately. First identify and document them; then correct them.
